Fri, 19 Jul 2019 10:24:23 log_helper.py[line:27] INFO sql执行失败:('table financial_detail already exists',) query:create table financial_detail(id INTEGER PRIMARY KEY autoincrement, cdate DATETIME , qtype TEXT ,specific_amount NUMBER(38,4));
		create table financial_dict(id INTEGER PRIMARY KEY autoincrement, cdate DATETIME , qtype TEXT ,specific_amount NUMBER(38,4), cycle INTEGER);
		create table financial(id INTEGER PRIMARY KEY autoincrement,dictid INTEGER,detailid INTEGER, cdate DATETIME , qtype TEXT ,specific_amount NUMBER(38,4));
Traceback (most recent call last):
  File "C:\Users\henry.zhangtj\AppData\Local\Programs\Python\Python37\b\dbop.py", line 109, in execute
    result = self.cursor.executescript(query)
sqlite3.OperationalError: table financial_detail already exists

程序调用堆栈的日志：<string>(<module>:1)->run.py(main:144)->run.py(runcode:474)->main.py(<module>:159)->main.py(main:144)->db_helper.py(table_check:27)->db_helper.py(initialize:37)->dbop.py(execute:112)->log_helper.py(error:22)->

Fri, 19 Jul 2019 10:27:38 log_helper.py[line:27] INFO type:<class 'sqlite3.ProgrammingError'>value:Cannot operate on a closed database.
trace:
Traceback (most recent call last):
  File "C:\Users\henry.zhangtj\AppData\Local\Programs\Python\Python37\b\db_helper.py", line 37, in initialize
    db.execute(csql)
  File "C:\Users\henry.zhangtj\AppData\Local\Programs\Python\Python37\b\dbop.py", line 133, in execute
    self.cursor.close()
sqlite3.ProgrammingError: Cannot operate on a closed database.

程序调用堆栈的日志：<string>(<module>:1)->run.py(main:144)->run.py(runcode:474)->main.py(<module>:159)->main.py(main:146)->db_helper.py(initialize:37)->dbop.py(__exit__:63)->log_helper.py(error:22)->

Fri, 19 Jul 2019 10:29:46 log_helper.py[line:27] INFO type:<class 'sqlite3.ProgrammingError'>value:Cannot operate on a closed database.
trace:
Traceback (most recent call last):
  File "C:\Users\henry.zhangtj\AppData\Local\Programs\Python\Python37\b\db_helper.py", line 37, in initialize
    db.execute(csql)
  File "C:\Users\henry.zhangtj\AppData\Local\Programs\Python\Python37\b\dbop.py", line 133, in execute
    self.cursor.close()
sqlite3.ProgrammingError: Cannot operate on a closed database.

程序调用堆栈的日志：<string>(<module>:1)->run.py(main:144)->run.py(runcode:474)->main.py(<module>:159)->main.py(main:146)->db_helper.py(initialize:37)->dbop.py(__exit__:63)->log_helper.py(error:22)->

Fri, 19 Jul 2019 10:32:31 log_helper.py[line:27] INFO type:<class 'sqlite3.ProgrammingError'>value:Cannot operate on a closed database.
trace:
Traceback (most recent call last):
  File "C:\Users\henry.zhangtj\AppData\Local\Programs\Python\Python37\b\db_helper.py", line 158, in query
    col,data=db.sqlite(qsql)
  File "C:\Users\henry.zhangtj\AppData\Local\Programs\Python\Python37\b\dbop.py", line 180, in sqlite
    self.cursor.close()#self.close_conn()
sqlite3.ProgrammingError: Cannot operate on a closed database.

程序调用堆栈的日志：<string>(<module>:1)->run.py(main:144)->run.py(runcode:474)->main.py(<module>:159)->main.py(main:149)->main.py(optype:60)->main.py(queryrecord:36)->db_helper.py(query:169)->dbop.py(__exit__:63)->log_helper.py(error:22)->

Fri, 19 Jul 2019 10:41:35 log_helper.py[line:27] INFO sql执行失败:('table financial_detail already exists',) query:create table financial_detail(id INTEGER PRIMARY KEY autoincrement, cdate DATETIME , qtype TEXT ,specific_amount NUMBER(38,4));
		create table financial_dict(id INTEGER PRIMARY KEY autoincrement, cdate DATETIME , qtype TEXT ,specific_amount NUMBER(38,4), cycle INTEGER);
		create table financial(id INTEGER PRIMARY KEY autoincrement,dictid INTEGER,detailid INTEGER, cdate DATETIME , qtype TEXT ,specific_amount NUMBER(38,4));
Traceback (most recent call last):
  File "C:\Users\henry.zhangtj\AppData\Local\Programs\Python\Python37\b\dbop.py", line 110, in execute
    result = self.cursor.executescript(query)
sqlite3.OperationalError: table financial_detail already exists

程序调用堆栈的日志：<string>(<module>:1)->run.py(main:144)->run.py(runcode:474)->main.py(<module>:159)->main.py(main:144)->db_helper.py(table_check:27)->db_helper.py(initialize:37)->dbop.py(execute:114)->log_helper.py(error:22)->

Fri, 26 Jul 2019 16:32:32 log_helper.py[line:27] INFO sql执行失败:('table financial_detail already exists',) query:create table financial_detail(id INTEGER PRIMARY KEY autoincrement, cdate DATETIME , qtype TEXT ,specific_amount NUMBER(38,4));
		create table financial_dict(id INTEGER PRIMARY KEY autoincrement, cdate DATETIME , qtype TEXT ,specific_amount NUMBER(38,4), cycle INTEGER);
		create table financial(id INTEGER PRIMARY KEY autoincrement,dictid INTEGER,detailid INTEGER, cdate DATETIME , qtype TEXT ,specific_amount NUMBER(38,4));
Traceback (most recent call last):
  File "D:\Apython\account_calculator_v2\dbop.py", line 110, in execute
    result = self.cursor.executescript(query)
sqlite3.OperationalError: table financial_detail already exists

程序调用堆栈的日志：main.py(<module>:204)->main.py(main:187)->db_helper.py(table_check:27)->db_helper.py(initialize:37)->dbop.py(execute:114)->log_helper.py(error:22)->

